<?xml version="1.0"?>
<!--
  Robot: my_robot
  Generated by: LinkForge v1.2.3
  https://github.com/arounamounchili/linkforge
  Date: 2026-02-26 12:13:43
-->
<robot name="my_robot">
  <!-- Links -->
  <link name="left_mechanical_track">
    <visual>
      <origin xyz="0 0 0" rpy="0 0 0" />
      <geometry>
        <mesh filename="package://robot_navigation/meshes/left_mechanical_track_visual.obj" />
      </geometry>
    </visual>
    <inertial>
      <mass value="1" />
      <inertia ixx="1044.106727" ixy="0.013385" ixz="0.014128" iyy="569.298246" iyz="-311.486351" izz="526.407705" />
    </inertial>
  </link>
  <link name="right_mechanical_track">
    <visual>
      <origin xyz="0.000001 0 0" rpy="0 0 0" />
      <geometry>
        <mesh filename="package://robot_navigation/meshes/right_mechanical_track_visual.obj" />
      </geometry>
    </visual>
    <inertial>
      <mass value="1" />
      <inertia ixx="1044.106787" ixy="0.134871" ixz="0.000392" iyy="235.635988" iyz="-2.047673" izz="860.070068" />
    </inertial>
  </link>
  <link name="chassis">
    <visual>
      <origin xyz="0.022589 -0.020235 -3.422767" rpy="0 0 0" />
      <geometry>
        <mesh filename="package://robot_navigation/meshes/chassis_visual.obj" />
      </geometry>
    </visual>
    <collision>
      <origin xyz="0 0 3.556792" rpy="0 0 0" />
      <geometry>
        <box size="58.12825 70 33" />
      </geometry>
    </collision>
    <inertial>
      <mass value="1" />
      <inertia ixx="499.083333" ixy="0" ixz="0" iyy="372.324455" iyz="0" izz="689.907789" />
    </inertial>
  </link>
  <link name="right_master_wheel">
    <visual>
      <geometry>
        <mesh filename="package://robot_navigation/meshes/right_master_wheel_visual.obj" />
      </geometry>
    </visual>
    <collision>
      <origin xyz="-0.802914 0.000914 -0.000025" rpy="0 1.570796 0" />
      <geometry>
        <cylinder radius="20.447336" length="20.70372" />
      </geometry>
    </collision>
    <inertial>
      <mass value="1" />
      <inertia ixx="140.243725" ixy="0" ixz="0" iyy="140.243725" iyz="0" izz="209.046779" />
    </inertial>
  </link>
  <link name="base_link">
    <inertial>
      <mass value="1" />
      <inertia ixx="1" ixy="0" ixz="0" iyy="1" iyz="0" izz="1" />
    </inertial>
  </link>
  <link name="right_slave_wheel">
    <visual>
      <geometry>
        <mesh filename="package://robot_navigation/meshes/right_slave_wheel_visual.obj" />
      </geometry>
    </visual>
    <collision>
      <origin xyz="-0.466064 0 -0.000009" rpy="0 1.570796 0" />
      <geometry>
        <cylinder radius="20.425734" length="20.702394" />
      </geometry>
    </collision>
    <inertial>
      <mass value="1" />
      <inertia ixx="140.018409" ixy="0" ixz="0" iyy="140.018409" iyz="0" izz="208.605296" />
    </inertial>
  </link>
  <link name="left_slave_wheel">
    <visual>
      <origin xyz="0 0 0" rpy="0 0 0" />
      <geometry>
        <mesh filename="package://robot_navigation/meshes/left_slave_wheel_visual.obj" />
      </geometry>
    </visual>
    <collision>
      <origin xyz="-0.466065 0 -0.000009" rpy="0 1.570796 0" />
      <geometry>
        <cylinder radius="20.425734" length="20.702394" />
      </geometry>
    </collision>
    <inertial>
      <mass value="1" />
      <inertia ixx="140.018409" ixy="0" ixz="0" iyy="140.018409" iyz="0" izz="208.605296" />
    </inertial>
  </link>
  <link name="left_master_wheel">
    <visual>
      <origin xyz="0 0 0" rpy="0 0 0" />
      <geometry>
        <mesh filename="package://robot_navigation/meshes/left_master_wheel_visual.obj" />
      </geometry>
    </visual>
    <collision>
      <origin xyz="-0.802913 0.000912 -0.000025" rpy="0 1.570796 0" />
      <geometry>
        <cylinder radius="20.447313" length="20.70372" />
      </geometry>
    </collision>
    <inertial>
      <mass value="1" />
      <inertia ixx="140.243491" ixy="0" ixz="0" iyy="140.243491" iyz="0" izz="209.046311" />
    </inertial>
  </link>
  <!-- Joints -->
  <joint name="left_mechanical_track_joint" type="revolute">
    <origin xyz="39.500122 0.120039 8.070752" rpy="-0.816489 0 0" />
    <parent link="base_link" />
    <child link="left_mechanical_track" />
    <axis xyz="0 0 1" />
    <limit effort="10" velocity="1" lower="-3.141593" upper="3.141593" />
  </joint>
  <joint name="right_mechanical_track_joint" type="revolute">
    <origin xyz="-39.393196 -0.179047 8.07074" rpy="3.141593 0 0.000191" />
    <parent link="base_link" />
    <child link="right_mechanical_track" />
    <axis xyz="0 0 1" />
    <limit effort="10" velocity="1" lower="-3.141593" upper="3.141593" />
  </joint>
  <joint name="chassis_joint" type="fixed">
    <origin xyz="0 0 12.943208" rpy="0 0 0" />
    <parent link="base_link" />
    <child link="chassis" />
  </joint>
  <joint name="right_master_wheel_joint" type="continuous">
    <origin xyz="-38.432346 26.727301 -4.946648" rpy="0 0 0" />
    <parent link="chassis" />
    <child link="right_master_wheel" />
    <axis xyz="0 0 1" />
    <limit effort="10" velocity="1" />
  </joint>
  <joint name="right_slave_wheel_joint" type="continuous">
    <origin xyz="-38.960999 -26.727301 -4.946648" rpy="0 0 0" />
    <parent link="chassis" />
    <child link="right_slave_wheel" />
    <axis xyz="0 0 1" />
    <limit effort="10" velocity="1" />
  </joint>
  <joint name="left_slave_wheel_joint" type="continuous">
    <origin xyz="38.960999 26.727301 -4.946648" rpy="0 0 -3.141593" />
    <parent link="chassis" />
    <child link="left_slave_wheel" />
    <axis xyz="0 0 1" />
    <limit effort="10" velocity="1" />
  </joint>
  <joint name="left_master_wheel_joint" type="continuous">
    <origin xyz="38.432301 -26.727301 -4.946648" rpy="0 0 -3.141593" />
    <parent link="chassis" />
    <child link="left_master_wheel" />
    <axis xyz="0 0 1" />
    <limit effort="10" velocity="1" />
  </joint>
</robot>